#VRML_SIM R2023a utf8

EXTERNPROTO "https://raw.githubusercontent.com/cyberbotics/webots/R2023a/projects/objects/backgrounds/protos/TexturedBackground.proto"
EXTERNPROTO "https://raw.githubusercontent.com/cyberbotics/webots/R2023a/projects/objects/backgrounds/protos/TexturedBackgroundLight.proto"
EXTERNPROTO "https://raw.githubusercontent.com/cyberbotics/webots/R2023a/projects/objects/floors/protos/RectangleArena.proto"
EXTERNPROTO "https://raw.githubusercontent.com/cyberbotics/webots/R2023a/projects/appearances/protos/Parquetry.proto"
EXTERNPROTO "../protos/SLRC_supervisor_v1.proto"

WorldInfo {
  contactProperties [
    ContactProperties {
    }
  ]
}
Viewpoint {
  orientation -0.0021514534628864954 0.9999904720997361 0.003798283525995457 1.0320573388689787
  position 0.014277199365626478 1.1728366915660673 0.49006838229701494
}
TexturedBackground {
}
TexturedBackgroundLight {
}
RectangleArena {
  translation -0.62 0 0
  floorSize 2.7 2.7
  floorTileSize 5 5
  floorAppearance Parquetry {
    type "dark strip"
    colorOverride 0 0 0
    textureTransform TextureTransform {
    }
  }
}
DEF box_3 Solid {
  translation -1.73568 -1.07485 0.02499509500075154
  rotation -0.5773059651320007 0.5774388671071756 0.5773059651320007 2.0942622106153297
  children [
    DEF box_3_shape Shape {
      appearance PBRAppearance {
        baseColor 1 0 0
        metalness 0
      }
      geometry Box {
        size 0.05 0.05 0.05
      }
    }
  ]
  name "solid(4)"
  boundingObject USE box_3_shape
  physics Physics {
    density 100
  }
  linearVelocity -5.849264067672048e-17 2.369666825554338e-17 -5.8716054240903655e-12
  angularVelocity -1.3322676295501877e-15 -1.998401444325281e-15 1.740560788650022e-16
}
DEF box_2 Solid {
  translation 0.4800000000000835 -1.089999999999917 0.01999748864038483
  rotation 0.07135661524000117 -0.12305707980733632 0.9898308888748529 3.381549462006975e-15
  children [
    DEF box_2_shape Shape {
      appearance PBRAppearance {
        baseColor 0 1 0
        metalness 0
      }
      geometry Box {
        size 0.04 0.04 0.04
      }
    }
  ]
  name "solid(3)"
  boundingObject USE box_2_shape
  physics Physics {
    density 100
  }
  linearVelocity -3.051533040507809e-17 -2.1091579303813112e-17 -3.0064839506849174e-12
  angularVelocity 2.0328790734103196e-15 -3.04931861011548e-15 5.660768125022418e-16
}
DEF box_1 Solid {
  translation 0.185701 0.832091 0.014998938292412948
  rotation -0.24920270873689765 0.6847985141478452 0.6847985141478452 -2.6531363922050266
  children [
    DEF box_1_shape Shape {
      appearance PBRAppearance {
        baseColor 0 0 1
        metalness 0
      }
      geometry Box {
        size 0.03 0.03 0.03
      }
    }
  ]
  name "solid(2)"
  boundingObject USE box_1_shape
  physics Physics {
    density 100
  }
  linearVelocity 2.197298664681701e-17 -7.226068033282038e-17 1.740313864211442e-08
  angularVelocity 4.283267841918037e-15 -2.0077818008990815e-15 -8.745066910026326e-16
}
DEF maze Solid {
  translation -1.93 1.32 -0.00589861
  rotation 1 0 0 1.5708
  scale 0.001 0.001 0.001
  children [
    DEF maze_shape Shape {
      appearance PBRAppearance {
        metalness 0
      }
      geometry Mesh {
        url [
          "../solid bodies/arena/webotsArena.STL"
        ]
      }
      castShadows FALSE
    }
  ]
}
DEF supervisor SLRC_supervisor_v1 {
}
DEF robot Robot {
  translation 0.3248046082740412 1.1514034629693215 0.02682502320169497
  rotation 0.0003103378391986564 3.879176801411403e-05 0.9999999510928109 3.1399718000109806
  children [
    SliderJoint {
      jointParameters JointParameters {
        position 0.09499806441312172
      }
      device [
        LinearMotor {
          name "linear_motor"
          minPosition -4.218299627066446e-07
          maxPosition 0.22
        }
      ]
      endPoint Solid {
        translation 0.08 -1.00975e-09 0.20399877369433037
        rotation -0.0003146494480905743 0.9999999504316027 -1.1511583224783515e-05 8.626113732216398e-08
        children [
          Solid {
            translation 0.05 0 0
            children [
              DEF ds_upper DistanceSensor {
                rotation 0 1 0 1.57
                children [
                  Shape {
                    appearance PBRAppearance {
                      baseColor 0 0.3 1
                      metalness 0
                    }
                    geometry Box {
                      size 0.01 0.01 0.01
                    }
                  }
                ]
                name "ds upper"
              }
              DEF right_arm_slider SliderJoint {
                jointParameters JointParameters {
                  position 4.387853267343724e-10
                  axis 0 1 0
                }
                device [
                  DEF right_arm LinearMotor {
                    name "right_arm"
                    minPosition -2.3875475041314083e-10
                    maxPosition 0.03
                  }
                ]
                endPoint Solid {
                  translation 9.29507026903309e-11 -0.03999999924704551 -0.015000329980158406
                  rotation 0.6956266012071046 0.7184034553067985 0.00032725571740921497 7.220339812441717e-09
                  children [
                    DEF leftarm Shape {
                      appearance PBRAppearance {
                        baseColor 0.6 0 0.4
                        metalness 0
                      }
                      geometry Box {
                        size 0.015 0.01 0.04
                      }
                    }
                  ]
                  name "solid(1)"
                  boundingObject USE leftarm
                  physics Physics {
                  }
                  translationStep 0.001
                  linearVelocity -0.10266949281770192 0.00013607077313510188 -0.0008726693180251355
                  angularVelocity 0.00018189103548211697 -0.010378385809571676 -9.826635874581039e-05
                }
              }
              DEF left_arm_slider SliderJoint {
                jointParameters JointParameters {
                  position -7.856265510966666e-10
                  axis 0 -1 0
                }
                device [
                  DEF left_arm LinearMotor {
                    name "left_arm"
                    minPosition -1.9540619122793146e-12
                    maxPosition 0.03
                  }
                ]
                endPoint Solid {
                  translation 1.0701262098677944e-10 0.04000000067018976 -0.015000463389482951
                  rotation -0.7259044147224842 0.6877955035193694 -0.00035499992238877256 1.0590656669932782e-08
                  children [
                    DEF leftarm Shape {
                      appearance PBRAppearance {
                        baseColor 0.6 0 0.4
                        metalness 0
                      }
                      geometry Box {
                        size 0.015 0.01 0.04
                      }
                    }
                  ]
                  boundingObject USE leftarm
                  physics Physics {
                  }
                  translationStep 0.001
                  linearVelocity -0.1026773246854019 0.0001360836677086454 -0.0008885668943798003
                  angularVelocity 0.00018189266621515922 -0.010378385812239582 -9.826660962480761e-05
                }
              }
              DEF front_arm_slider SliderJoint {
                jointParameters JointParameters {
                  position -5.00197106318835e-07
                  axis -1 0 0
                }
                device [
                  DEF front_arm LinearMotor {
                    name "front_arm"
                    minPosition -1.0584611553239796e-10
                    maxPosition 0.03
                  }
                ]
                endPoint Solid {
                  translation 0.04000049873835597 7.451483874376663e-11 -0.01500284331229873
                  rotation 5.8611799576368095e-06 0.9999999995891897 2.8058283419770093e-05 1.0208835312190552e-07
                  children [
                    DEF leftarm Shape {
                      appearance PBRAppearance {
                        baseColor 0.6 0 0.4
                        metalness 0
                      }
                      geometry Box {
                        size 0.01 0.04 0.04
                      }
                    }
                  ]
                  name "solid(2)"
                  boundingObject USE leftarm
                  physics Physics {
                  }
                  translationStep 0.001
                  linearVelocity -0.10267723518273167 0.00014008284400418152 -0.0012955429502918073
                  angularVelocity 0.000181891845738329 -0.01037838900087475 -9.826648407232945e-05
                }
              }
              DEF back_arm_slider SliderJoint {
                jointParameters JointParameters {
                  position -6.206189109688001e-08
                  axis 1 0 0
                }
                device [
                  DEF back_arm LinearMotor {
                    name "back_arm"
                    minPosition -1.4922542368456249e-12
                    maxPosition 0.03
                  }
                ]
                endPoint Solid {
                  translation -0.04000006189298246 8.252953875853564e-11 -0.015003085417633108
                  rotation 0.00012324637855219058 -0.9999999917933338 -3.4980888818052036e-05 5.341095070699061e-09
                  children [
                    DEF leftarm Shape {
                      appearance PBRAppearance {
                        baseColor 0.6 0 0.4
                        metalness 0
                      }
                      geometry Box {
                        size 0.01 0.04 0.04
                      }
                    }
                  ]
                  name "solid(3)"
                  boundingObject USE leftarm
                  physics Physics {
                  }
                  translationStep 0.001
                  linearVelocity -0.1026846580468313 0.00013215057678119395 -0.0004657496967100331
                  angularVelocity 0.0001818918527750673 -0.010378384624208311 -9.826648423393219e-05
                }
              }
              DEF crossbar Shape {
                appearance PBRAppearance {
                  baseColor 0.2 0.3 0.3
                  metalness 0
                }
                geometry Box {
                  size 0.01 0.1 0.01
                }
              }
            ]
            name "cross bar"
            boundingObject USE crossbar
            physics Physics {
            }
          }
          Solid {
            translation 0.04 0 0
            children [
              SliderJoint {
                jointParameters JointParameters {
                  position -3.5315963817281445e-07
                }
                device [
                  LinearMotor {
                  }
                ]
              }
            ]
          }
          DEF ab_shape Shape {
            appearance PBRAppearance {
              baseColor 0.1 0.5 1
              metalness 0
            }
            geometry Box {
              size 0.17 0.01 0.01
            }
          }
        ]
        name "solid(5)"
        boundingObject USE ab_shape
        physics Physics {
        }
        linearVelocity -0.10283955741960257 0.00013026538184599332 -0.0005590198710690103
        angularVelocity 0.0001818918517712926 -0.010378385212359682 -9.826648422253511e-05
      }
    }
    Solid {
      translation 0 0 0.06
      children [
        Shape {
          appearance PBRAppearance {
            baseColor 0.6 0.4 1
            metalness 0
          }
          geometry Box {
            size 0.01 0.01 0.33
          }
        }
      ]
      name "solid(4)"
    }
    DistanceSensor {
      translation 0.073 0.037 0
      children [
        DEF distant_sensor Shape {
          appearance PBRAppearance {
            baseColor 0 0 1
            metalness 0
          }
          geometry Box {
            size 0.01 0.01 0.01
          }
        }
      ]
      name "ds front left"
      boundingObject USE distant_sensor
      physics Physics {
      }
    }
    DEF ds_side_left1 DistanceSensor {
      translation 0.069 0.045 0.019
      rotation 0 0 1 1.5707903061004251
      children [
        DEF distant_sensor Shape {
          appearance PBRAppearance {
            baseColor 0 0 1
            metalness 0
          }
          geometry Box {
            size 0.01 0.01 0.01
          }
        }
      ]
      name "ds side left1"
      boundingObject USE distant_sensor
      physics Physics {
      }
    }
    DEF ds_side_left1 DistanceSensor {
      translation -0.069 0.045 0.019
      rotation 0 0 1 1.5707903061004251
      children [
        DEF distant_sensor Shape {
          appearance PBRAppearance {
            baseColor 0 0 1
            metalness 0
          }
          geometry Box {
            size 0.01 0.01 0.01
          }
        }
      ]
      name "ds side left2"
      boundingObject USE distant_sensor
      physics Physics {
      }
    }
    DEF ds DistanceSensor {
      translation 0.073 -0.037 0
      children [
        Shape {
          appearance PBRAppearance {
            baseColor 0 0 1
            metalness 0
          }
          geometry Box {
            size 0.01 0.01 0.01
          }
        }
      ]
      name "ds front right"
      boundingObject USE distant_sensor
      physics Physics {
      }
    }
    DEF ds_side_right DistanceSensor {
      translation 0.069 -0.045 0.02
      rotation 0 0 1 -1.57
      children [
        Shape {
          appearance PBRAppearance {
            baseColor 0 0 1
            metalness 0
          }
          geometry Box {
            size 0.01 0.01 0.01
          }
        }
      ]
      name "ds side right1"
      boundingObject USE distant_sensor
      physics Physics {
      }
    }
    DEF ds_side_right DistanceSensor {
      translation -0.069 -0.045 0.02
      rotation 0 0 1 -1.57
      children [
        Shape {
          appearance PBRAppearance {
            baseColor 0 0 1
            metalness 0
          }
          geometry Box {
            size 0.01 0.01 0.01
          }
        }
      ]
      name "ds side right2"
      boundingObject USE distant_sensor
      physics Physics {
      }
    }
    HingeJoint {
      jointParameters HingeJointParameters {
        position 290.3721315648182
        axis 0 1 0
        anchor 0.05 0.056 -0.007
      }
      device [
        DEF front_left_wheel RotationalMotor {
          name "front_left_wheel"
        }
      ]
      endPoint Solid {
        translation 0.0499999030368457 0.05600000006485646 -0.00700464802014556
        rotation -0.6629645758725022 -0.5297775075389111 0.5289742561259974 4.313861159473039
        children [
          DEF wheel Shape {
            appearance PBRAppearance {
              baseColor 0 0 0
              metalness 0
            }
            geometry Cylinder {
              height 0.01
              radius 0.02
            }
          }
        ]
        boundingObject USE wheel
        physics DEF physics_wheel Physics {
        }
        linearVelocity -0.10065179037373094 0.00016195053469580587 -4.656064486626901e-05
        angularVelocity -0.007946309701543398 -5.034371383029064 0.0003184589168559541
      }
    }
    HingeJoint {
      jointParameters HingeJointParameters {
        position 215.15260928269552
        axis 0 1 0
        anchor 0.05 -0.056 -0.007
      }
      device [
        DEF front_right_wheel RotationalMotor {
          name "front_right_wheel"
        }
      ]
      endPoint Solid {
        translation 0.050005327126713885 -0.0559999932750882 -0.006995103718182662
        rotation -0.5992516318431219 -0.5663069919171896 0.5658567598244807 4.222032245850415
        children [
          USE wheel
        ]
        name "solid(1)"
        boundingObject USE wheel
        physics USE physics_wheel
        linearVelocity -0.10068771302498279 0.00016199330887262182 -4.685121578098159e-05
        angularVelocity -0.007946336034684216 -5.034371763967785 0.0003184690326180434
      }
    }
    HingeJoint {
      jointParameters HingeJointParameters {
        position 290.43098801565424
        axis 0 1 0
        anchor -0.05 0.056 -0.007
      }
      device [
        DEF left_back_wheel RotationalMotor {
          name "left_back_wheel"
        }
      ]
      endPoint Solid {
        translation -0.049995594984703164 0.056000001505638594 -0.0070023387761246805
        rotation -0.6406131271546653 -0.5431777853060726 0.5427455341751886 4.281812038718824
        children [
          USE wheel
        ]
        name "solid(2)"
        boundingObject USE wheel
        physics USE physics_wheel
        linearVelocity -0.10069638906130353 0.0001558711280013589 0.0009691241654485219
        angularVelocity -0.007946197098648548 -5.034371913479029 0.00031837204492201184
      }
    }
    DEF hing HingeJoint {
      jointParameters HingeJointParameters {
        position 215.18723388774532
        axis 0 1 0
        anchor -0.05 -0.056 -0.007
      }
      device [
        RotationalMotor {
          name "right_back_wheel"
        }
      ]
      endPoint Solid {
        translation -0.04999474723541198 -0.05599999851487053 -0.006996831896220442
        rotation -0.5859279155065966 -0.5732413610642075 0.5727851427851016 4.202303574625299
        children [
          USE wheel
        ]
        name "solid(3)"
        boundingObject USE wheel
        physics USE physics_wheel
        linearVelocity -0.1007129860689651 0.00015588599523166352 0.0009898832263026962
        angularVelocity -0.00794619742612003 -5.034371951018395 0.00031838042075392166
      }
    }
    DEF body Shape {
      appearance PBRAppearance {
        baseColor 0 0.2 0.3
        metalness 0
      }
      geometry Box {
        size 0.15 0.1 0.03
      }
    }
  ]
  name "myrobot"
  boundingObject USE body
  physics Physics {
  }
  controller "my_object_detection"
  linearVelocity -0.10075802111428465 0.0001576778135188159 0.0004758003806394302
  angularVelocity 0.00018189191952364987 -0.010378345234954503 -9.826648577179578e-05
}
