#VRML_SIM R2023a utf8

EXTERNPROTO "https://raw.githubusercontent.com/cyberbotics/webots/R2023a/projects/objects/backgrounds/protos/TexturedBackground.proto"
EXTERNPROTO "https://raw.githubusercontent.com/cyberbotics/webots/R2023a/projects/objects/backgrounds/protos/TexturedBackgroundLight.proto"
EXTERNPROTO "https://raw.githubusercontent.com/cyberbotics/webots/R2023a/projects/objects/floors/protos/RectangleArena.proto"
EXTERNPROTO "https://raw.githubusercontent.com/cyberbotics/webots/R2023a/projects/appearances/protos/Parquetry.proto"
EXTERNPROTO "../protos/SLRC_supervisor_v1.proto"

WorldInfo {
  contactProperties [
    ContactProperties {
    }
  ]
}
Viewpoint {
  orientation 0.3297973077607539 0.332727900360152 -0.8834737574572793 1.6855816975700022
  position -1.4256155946904727 2.0910235427241077 1.4317462273007084
}
TexturedBackground {
}
TexturedBackgroundLight {
}
RectangleArena {
  translation -0.62 0 0
  floorSize 2.7 2.7
  floorTileSize 5 5
  floorAppearance Parquetry {
    type "dark strip"
    colorOverride 0 0 0
    textureTransform TextureTransform {
    }
  }
}
DEF box_3 Solid {
  translation -1.73568 -1.07485 0.024995095000000744
  rotation -0.5773059651320006 0.5774388671071756 0.5773059651320007 2.0942622106153297
  children [
    DEF box_3_shape Shape {
      appearance PBRAppearance {
        baseColor 1 0 0
        metalness 0
      }
      geometry Box {
        size 0.05 0.05 0.05
      }
    }
  ]
  name "solid(4)"
  boundingObject USE box_3_shape
  physics Physics {
    density 100
  }
  linearVelocity -3.9559460238865795e-17 -1.0431319843709442e-17 -5.861977570020749e-15
  angularVelocity 2.3665827156630354e-30 -1.998401444325283e-15 -3.0054717390575007e-16
}
DEF box_2 Solid {
  translation 0.4800000000000835 -1.089999999999917 0.019997488640000383
  rotation -0.08233128187079433 0.01157485826271631 0.9965377979192309 3.3902195201528814e-15
  children [
    DEF box_2_shape Shape {
      appearance PBRAppearance {
        baseColor 0 1 0
        metalness 0
      }
      geometry Box {
        size 0.04 0.04 0.04
      }
    }
  ]
  name "solid(3)"
  boundingObject USE box_2_shape
  physics Physics {
    density 100
  }
  linearVelocity 5.557504112350528e-17 -9.100145853063221e-18 -2.9837243786797043e-15
  angularVelocity -1.0164395367051612e-15 1.0164395367051612e-15 -3.7455390880836257e-16
}
DEF box_1 Solid {
  translation 0.185701 0.832091 0.014998940519999998
  rotation -0.24920270873689784 0.684798514147845 0.6847985141478452 -2.6531363922050266
  children [
    DEF box_1_shape Shape {
      appearance PBRAppearance {
        baseColor 0 0 1
        metalness 0
      }
      geometry Box {
        size 0.03 0.03 0.03
      }
    }
  ]
  name "solid(2)"
  boundingObject USE box_1_shape
  physics Physics {
    density 100
  }
  linearVelocity -8.982434926774526e-17 -3.628266945960645e-17 4.11193712824132e-17
  angularVelocity 2.6770424011987812e-15 -8.031127203596316e-15 1.1165649919754975e-16
}
DEF maze Solid {
  translation -1.93 1.32 -0.00589861
  rotation 1 0 0 1.5708
  scale 0.001 0.001 0.001
  children [
    DEF maze_shape Shape {
      appearance PBRAppearance {
        metalness 0
      }
      geometry Mesh {
        url [
          "../solid bodies/arena/webotsArena.STL"
        ]
      }
      castShadows FALSE
    }
  ]
}
DEF supervisor SLRC_supervisor_v1 {
}
DEF robot Robot {
  translation -1.75 1.14989 0.0253944
  rotation -0.00034363541834467033 2.6530446781068978e-05 0.9999999406054156 -1.57
  children [
    GPS {
      translation 0 0 0.01
      children [
        Shape {
          appearance PBRAppearance {
            baseColor 0.6 0.4 1
            metalness 0
          }
          geometry Cylinder {
            height 0.01
            radius 0.03
          }
        }
      ]
    }
    SliderJoint {
      jointParameters JointParameters {
        position -6.95234808917311e-07
      }
      device [
        LinearMotor {
          name "linear_motor"
          minPosition -4.218299627066446e-07
          maxPosition 0.22
        }
      ]
      endPoint Solid {
        translation 0.08 -1.00975e-09 0.10900001404639965
        rotation -0.0003146494480905743 0.9999999504316027 -1.1511583224783515e-05 8.626113732216398e-08
        children [
          Solid {
            translation 0.05 0 0
            children [
              DEF ds_upper DistanceSensor {
                rotation 0 1 0 1.57
                children [
                  Shape {
                    appearance PBRAppearance {
                      baseColor 0 0.3 1
                      metalness 0
                    }
                    geometry Box {
                      size 0.01 0.01 0.01
                    }
                  }
                ]
                name "ds upper"
              }
              DEF right_arm_slider SliderJoint {
                jointParameters JointParameters {
                  position -3.1222818890722334e-12
                  axis 0 1 0
                }
                device [
                  DEF right_arm LinearMotor {
                    name "right_arm"
                    minPosition -2.483719710004683e-10
                    maxPosition 0.03
                  }
                ]
                endPoint Solid {
                  translation 9.29507026903309e-11 -0.03999999968895312 -0.015000329980158406
                  rotation 0.6956266012071046 0.7184034553067985 0.00032725571740921497 7.220339812441717e-09
                  children [
                    DEF leftarm Shape {
                      appearance PBRAppearance {
                        baseColor 0.6 0 0.4
                        metalness 0
                      }
                      geometry Box {
                        size 0.015 0.01 0.04
                      }
                    }
                  ]
                  name "solid(1)"
                  boundingObject USE leftarm
                  physics Physics {
                  }
                  translationStep 0.001
                }
              }
              DEF left_arm_slider SliderJoint {
                jointParameters JointParameters {
                  position 3.1231406794708586e-12
                  axis 0 -1 0
                }
                device [
                  DEF left_arm LinearMotor {
                    name "left_arm"
                    minPosition -1.9540619122793146e-12
                    maxPosition 0.03
                  }
                ]
                endPoint Solid {
                  translation 1.0701262098677944e-10 0.03999999988144007 -0.015000463389482951
                  rotation -0.7259044147224842 0.6877955035193694 -0.00035499992238877256 1.0590656669932782e-08
                  children [
                    DEF leftarm Shape {
                      appearance PBRAppearance {
                        baseColor 0.6 0 0.4
                        metalness 0
                      }
                      geometry Box {
                        size 0.015 0.01 0.04
                      }
                    }
                  ]
                  boundingObject USE leftarm
                  physics Physics {
                  }
                  translationStep 0.001
                }
              }
              DEF front_arm_slider SliderJoint {
                jointParameters JointParameters {
                  position -1.0789739704695279e-10
                  axis -1 0 0
                }
                device [
                  DEF front_arm LinearMotor {
                    name "front_arm"
                    minPosition -1.0584611553239796e-10
                    maxPosition 0.03
                  }
                ]
                endPoint Solid {
                  translation 0.03999999864914705 7.451483874376663e-11 -0.01500284331229873
                  rotation 5.8611799576368095e-06 0.9999999995891897 2.8058283419770093e-05 1.0208835312190552e-07
                  children [
                    DEF leftarm Shape {
                      appearance PBRAppearance {
                        baseColor 0.6 0 0.4
                        metalness 0
                      }
                      geometry Box {
                        size 0.01 0.04 0.04
                      }
                    }
                  ]
                  name "solid(2)"
                  boundingObject USE leftarm
                  physics Physics {
                  }
                  translationStep 0.001
                }
              }
              DEF back_arm_slider SliderJoint {
                jointParameters JointParameters {
                  position 1.0789890674349326e-10
                  axis 1 0 0
                }
                device [
                  DEF back_arm LinearMotor {
                    name "back_arm"
                    minPosition -1.0113443855271692e-10
                    maxPosition 0.03
                  }
                ]
                endPoint Solid {
                  translation -0.03999999972319246 8.252953875853564e-11 -0.015003085417633108
                  rotation 0.00012324637855219058 -0.9999999917933338 -3.4980888818052036e-05 5.341095070699061e-09
                  children [
                    DEF leftarm Shape {
                      appearance PBRAppearance {
                        baseColor 0.6 0 0.4
                        metalness 0
                      }
                      geometry Box {
                        size 0.01 0.04 0.04
                      }
                    }
                  ]
                  name "solid(3)"
                  boundingObject USE leftarm
                  physics Physics {
                  }
                  translationStep 0.001
                }
              }
              DEF crossbar Shape {
                appearance PBRAppearance {
                  baseColor 0.2 0.3 0.3
                  metalness 0
                }
                geometry Box {
                  size 0.01 0.1 0.01
                }
              }
            ]
            name "cross bar"
            boundingObject USE crossbar
            physics Physics {
            }
          }
          Solid {
            translation 0.04 0 0
            children [
              SliderJoint {
                jointParameters JointParameters {
                  position -3.5315963817281445e-07
                }
                device [
                  LinearMotor {
                  }
                ]
              }
            ]
          }
          DEF ab_shape Shape {
            appearance PBRAppearance {
              baseColor 0.1 0.5 1
              metalness 0
            }
            geometry Box {
              size 0.17 0.01 0.01
            }
          }
        ]
        name "solid(5)"
        boundingObject USE ab_shape
        physics Physics {
        }
      }
    }
    Solid {
      translation 0 0 0.13
      children [
        Shape {
          appearance PBRAppearance {
            baseColor 0.6 0.4 1
            metalness 0
          }
          geometry Box {
            size 0.01 0.01 0.25
          }
        }
      ]
      name "solid(4)"
    }
    DistanceSensor {
      translation 0.073 0.037 0
      children [
        DEF distant_sensor Shape {
          appearance PBRAppearance {
            baseColor 0 0 1
            metalness 0
          }
          geometry Box {
            size 0.01 0.01 0.01
          }
        }
      ]
      name "ds front left"
      boundingObject USE distant_sensor
      physics Physics {
      }
    }
    DEF ds_side_left1 DistanceSensor {
      translation 0.069 0.045 0.019
      rotation 0 0 1 1.5707903061004251
      children [
        DEF distant_sensor Shape {
          appearance PBRAppearance {
            baseColor 0 0 1
            metalness 0
          }
          geometry Box {
            size 0.01 0.01 0.01
          }
        }
      ]
      name "ds side left1"
      boundingObject USE distant_sensor
      physics Physics {
      }
    }
    DEF ds_side_left1 DistanceSensor {
      translation -0.069 0.045 0.019
      rotation 0 0 1 1.5707903061004251
      children [
        DEF distant_sensor Shape {
          appearance PBRAppearance {
            baseColor 0 0 1
            metalness 0
          }
          geometry Box {
            size 0.01 0.01 0.01
          }
        }
      ]
      name "ds side left2"
      boundingObject USE distant_sensor
      physics Physics {
      }
    }
    DEF ds DistanceSensor {
      translation 0.073 -0.037 0
      children [
        Shape {
          appearance PBRAppearance {
            baseColor 0 0 1
            metalness 0
          }
          geometry Box {
            size 0.01 0.01 0.01
          }
        }
      ]
      name "ds front right"
      boundingObject USE distant_sensor
      physics Physics {
      }
    }
    DEF ds_side_right DistanceSensor {
      translation 0.069 -0.045 0.02
      rotation 0 0 1 -1.57
      children [
        Shape {
          appearance PBRAppearance {
            baseColor 0 0 1
            metalness 0
          }
          geometry Box {
            size 0.01 0.01 0.01
          }
        }
      ]
      name "ds side right1"
      boundingObject USE distant_sensor
      physics Physics {
      }
    }
    DEF ds_side_right DistanceSensor {
      translation -0.069 -0.045 0.02
      rotation 0 0 1 -1.57
      children [
        Shape {
          appearance PBRAppearance {
            baseColor 0 0 1
            metalness 0
          }
          geometry Box {
            size 0.01 0.01 0.01
          }
        }
      ]
      name "ds side right2"
      boundingObject USE distant_sensor
      physics Physics {
      }
    }
    HingeJoint {
      jointParameters HingeJointParameters {
        position 900.1651129580608
        axis 0 1 0
        anchor 0.05 0.056 -0.007
      }
      device [
        DEF front_left_wheel RotationalMotor {
          name "front_left_wheel"
        }
      ]
      endPoint Solid {
        translation 0.04999842830478972 0.05600000006485646 -0.007004375301965898
        rotation 0.5385441967981871 0.5962580919832514 -0.5953540424314661 2.1523143433898655
        children [
          DEF wheel Shape {
            appearance PBRAppearance {
              baseColor 0 0 0
              metalness 0
            }
            geometry Cylinder {
              height 0.01
              radius 0.02
            }
          }
        ]
        boundingObject USE wheel
        physics DEF physics_wheel Physics {
        }
      }
    }
    HingeJoint {
      jointParameters HingeJointParameters {
        position 824.9455906597013
        axis 0 1 0
        anchor 0.05 -0.056 -0.007
      }
      device [
        DEF front_right_wheel RotationalMotor {
          name "front_right_wheel"
        }
      ]
      endPoint Solid {
        translation 0.050006608758413895 -0.0559999932750882 -0.006997054466620905
        rotation 0.4748908320003616 0.6225330021964459 -0.6220380686568019 2.254257579726584
        children [
          USE wheel
        ]
        name "solid(1)"
        boundingObject USE wheel
        physics USE physics_wheel
      }
    }
    HingeJoint {
      jointParameters HingeJointParameters {
        position 900.22398873696
        axis 0 1 0
        anchor -0.05 0.056 -0.007
      }
      device [
        DEF left_back_wheel RotationalMotor {
          name "left_back_wheel"
        }
      ]
      endPoint Solid {
        translation -0.049996568848465886 0.056000001505638594 -0.007003619562497955
        rotation 0.5160795095645611 0.6059067614179502 -0.605424591733449 2.188086998501977
        children [
          USE wheel
        ]
        name "solid(2)"
        boundingObject USE wheel
        physics USE physics_wheel
      }
    }
    DEF hing HingeJoint {
      jointParameters HingeJointParameters {
        position 824.9802345996526
        axis 0 1 0
        anchor -0.05 -0.056 -0.007
      }
      device [
        RotationalMotor {
          name "right_back_wheel"
        }
      ]
      endPoint Solid {
        translation -0.04999401190395633 -0.05599999851487053 -0.0069986691644928715
        rotation 0.46169629239760235 0.6274802755018356 -0.6269808908112336 2.2759107299345676
        children [
          USE wheel
        ]
        name "solid(3)"
        boundingObject USE wheel
        physics USE physics_wheel
      }
    }
    DEF body Shape {
      appearance PBRAppearance {
        baseColor 0 0.2 0.3
        metalness 0
      }
      geometry Box {
        size 0.15 0.1 0.03
      }
    }
  ]
  name "myrobot"
  boundingObject USE body
  physics Physics {
  }
  controller "my_keyboad_controller"
}
