#VRML_SIM R2023a utf8

EXTERNPROTO "https://raw.githubusercontent.com/cyberbotics/webots/R2023a/projects/objects/backgrounds/protos/TexturedBackground.proto"
EXTERNPROTO "https://raw.githubusercontent.com/cyberbotics/webots/R2023a/projects/objects/backgrounds/protos/TexturedBackgroundLight.proto"
EXTERNPROTO "https://raw.githubusercontent.com/cyberbotics/webots/R2023a/projects/objects/floors/protos/RectangleArena.proto"
EXTERNPROTO "https://raw.githubusercontent.com/cyberbotics/webots/R2023a/projects/appearances/protos/Parquetry.proto"
EXTERNPROTO "../protos/SLRC_supervisor_v1.proto"

WorldInfo {
  contactProperties [
    ContactProperties {
    }
  ]
}
Viewpoint {
  orientation -0.22038608717652572 -0.7349914432041801 0.6412624665420996 5.40842641979556
  position -2.680976651084496 1.9417030346465438 1.100216029876046
}
TexturedBackground {
}
TexturedBackgroundLight {
}
RectangleArena {
  translation -0.62 0 0
  floorSize 2.7 2.7
  floorTileSize 5 5
  floorAppearance Parquetry {
    type "dark strip"
    colorOverride 0 0 0
    textureTransform TextureTransform {
    }
  }
}
DEF box_3 Solid {
  translation -1.734915042213331 0.8521450054297312 0.024995095000000012
  rotation -0.5759422431166107 0.5801560696809211 0.5759422431166106 2.0901915149905794
  children [
    DEF box_3_shape Shape {
      appearance PBRAppearance {
        baseColor 1 0 0
        metalness 0
      }
      geometry Box {
        size 0.05 0.05 0.05
      }
    }
  ]
  name "solid(1)"
  boundingObject USE box_3_shape
  physics Physics {
    density 100
  }
  recognitionColors [
    1 0 0
  ]
  linearVelocity 6.877647943924467e-17 7.587229877316817e-18 -8.180227979541013e-18
  angularVelocity 2.172387302899901e-16 3.2085072226923983e-15 -4.6963224097078445e-16
}
DEF box_3 Solid {
  translation -1.73568 -1.07485 0.024995095759685126
  rotation -0.5773059651320005 0.5774388671071758 0.5773059651320006 2.0942622106153292
  children [
    DEF box_3_shape Shape {
      appearance PBRAppearance {
        baseColor 1 0 0
        metalness 0
      }
      geometry Box {
        size 0.05 0.05 0.05
      }
    }
  ]
  name "solid(4)"
  boundingObject USE box_3_shape
  physics Physics {
    density 100
  }
  recognitionColors [
    1 0 0
  ]
}
DEF box_2 Solid {
  translation 0.4800000000000835 -1.089999999999917 0.01999748902897272
  rotation 0.03809692492456015 -0.06456444646100369 0.9971860691789053 2.918651922625959e-15
  children [
    DEF box_2_shape Shape {
      appearance PBRAppearance {
        baseColor 0 1 0
        metalness 0
      }
      geometry Box {
        size 0.04 0.04 0.04
      }
    }
  ]
  name "solid(3)"
  boundingObject USE box_2_shape
  physics Physics {
    density 100
  }
  recognitionColors [
    0 1 0
  ]
}
DEF box_1 Solid {
  translation 0.4595980661933159 1.125483838373481 0.014998940684101434
  rotation 0.9980963886078764 -0.043609626505594114 -0.04360962650559415 1.5727017512048829
  children [
    DEF box_1_shape Shape {
      appearance PBRAppearance {
        baseColor 0 0 1
        metalness 0
      }
      geometry Box {
        size 0.03 0.03 0.03
      }
    }
  ]
  name "solid(2)"
  boundingObject USE box_1_shape
  physics Physics {
    density 100
  }
  recognitionColors [
    0 0 1
  ]
}
DEF maze Solid {
  translation -1.93 1.32 -0.00589861
  rotation 1 0 0 1.5708
  scale 0.001 0.001 0.001
  children [
    DEF maze_shape Shape {
      appearance PBRAppearance {
        metalness 0
      }
      geometry Mesh {
        url [
          "../solid bodies/arena/webotsArena.STL"
        ]
      }
      castShadows FALSE
    }
  ]
}
DEF supervisor SLRC_supervisor_v1 {
}
DEF robot Robot {
  translation -1.7354776415589446 0.9820892220865395 0.026886360283099806
  rotation 0.0003689483465661488 0.0003272099474921531 -0.9999998784053765 1.5760497941076175
  children [
    InertialUnit {
      children [
        Shape {
          appearance PBRAppearance {
            baseColor 0.5 0.5 0.6
            metalness 0
          }
          geometry Box {
            size 0.01 0.01 0.01
          }
        }
      ]
    }
    GPS {
      translation 0 0 0.01
      children [
        Shape {
          appearance PBRAppearance {
            baseColor 0.6 0.4 1
            metalness 0
          }
          geometry Cylinder {
            height 0.01
            radius 0.03
          }
        }
      ]
    }
    SliderJoint {
      jointParameters JointParameters {
        position 0.1849993034901703
      }
      device [
        LinearMotor {
          name "linear_motor"
          minPosition -6.965098447313271e-07
          maxPosition 0.2
        }
      ]
      endPoint Solid {
        translation 0.0810161 -1.53463e-06 0.21399999994911442
        rotation -0.048623936771275106 0.9985423676294055 -0.02342760811359637 1.1701001132650412e-06
        children [
          Solid {
            translation 0.05 0 0
            children [
              Camera {
                translation 0 0 -0.002
                rotation 0 1 0 1.5708003061004252
                children [
                  Shape {
                    appearance PBRAppearance {
                      baseColor 0.101961 0.184314 0.560784
                      metalness 0
                    }
                    geometry Box {
                      size 0.01 0.01 0.01
                    }
                  }
                ]
                recognitionColors [
                  1 0 0
                ]
                recognition Recognition {
                }
              }
              DEF right_arm_slider SliderJoint {
                jointParameters JointParameters {
                  position -2.3520446652073597e-12
                  axis 0 1 0
                }
                device [
                  DEF right_arm LinearMotor {
                    name "right_arm"
                    minPosition -2.483719710004683e-10
                    maxPosition 0.03
                  }
                ]
                endPoint Solid {
                  translation 9.29507026903309e-11 -0.03999999968818288 -0.015000329980158406
                  rotation 0.6956266012071046 0.7184034553067985 0.00032725571740921497 7.220339812441717e-09
                  children [
                    DEF leftarm Shape {
                      appearance PBRAppearance {
                        baseColor 0.6 0 0.4
                        metalness 0
                      }
                      geometry Box {
                        size 0.015 0.01 0.04
                      }
                    }
                  ]
                  name "solid(1)"
                  boundingObject USE leftarm
                  physics Physics {
                  }
                  translationStep 0.001
                  linearVelocity -1.253500172944777e-12 1.1908602867804928e-12 4.407772150817571e-15
                  angularVelocity -3.7365608239441005e-14 -7.411696307306244e-15 -9.565876603342324e-12
                }
              }
              DEF left_arm_slider SliderJoint {
                jointParameters JointParameters {
                  position 2.3518231725394553e-12
                  axis 0 -1 0
                }
                device [
                  DEF left_arm LinearMotor {
                    name "left_arm"
                    minPosition -1.9540619122793146e-12
                    maxPosition 0.03
                  }
                ]
                endPoint Solid {
                  translation 1.0701262098677944e-10 0.03999999988221139 -0.015000463389482951
                  rotation -0.7259044147224842 0.6877955035193694 -0.00035499992238877256 1.0590656669932782e-08
                  children [
                    DEF leftarm Shape {
                      appearance PBRAppearance {
                        baseColor 0.6 0 0.4
                        metalness 0
                      }
                      geometry Box {
                        size 0.015 0.01 0.04
                      }
                    }
                  ]
                  boundingObject USE leftarm
                  physics Physics {
                  }
                  translationStep 0.001
                  linearVelocity -1.2578184361400219e-12 4.2414832164100407e-13 4.599814473019805e-15
                  angularVelocity -3.763234084513924e-14 2.1227392090237658e-14 -9.572421166783006e-12
                }
              }
              DEF front_arm_slider SliderJoint {
                jointParameters JointParameters {
                  position -1.0976798087914565e-10
                  axis -1 0 0
                }
                device [
                  DEF front_arm LinearMotor {
                    name "front_arm"
                    minPosition -1.0789960536767959e-10
                    maxPosition 0.03
                  }
                ]
                endPoint Solid {
                  translation 0.03999999865101763 7.451483874376663e-11 -0.01500284331229873
                  rotation 5.8611799576368095e-06 0.9999999995891897 2.8058283419770093e-05 1.0208835312190552e-07
                  children [
                    DEF leftarm Shape {
                      appearance PBRAppearance {
                        baseColor 0.6 0 0.4
                        metalness 0
                      }
                      geometry Box {
                        size 0.01 0.04 0.04
                      }
                    }
                  ]
                  name "solid(2)"
                  boundingObject USE leftarm
                  physics Physics {
                  }
                  translationStep 0.001
                  linearVelocity -1.6396391619158727e-12 8.095692024336608e-13 4.5768646034574645e-15
                  angularVelocity -1.5890376237626107e-14 -9.837164856740452e-15 -9.578842124763102e-12
                }
              }
              DEF back_arm_slider SliderJoint {
                jointParameters JointParameters {
                  position 1.0976802468122498e-10
                  axis 1 0 0
                }
                device [
                  DEF back_arm LinearMotor {
                    name "back_arm"
                    minPosition -1.0113443855271692e-10
                    maxPosition 0.03
                  }
                ]
                endPoint Solid {
                  translation -0.039999999721323336 8.252953875853564e-11 -0.015003085417633108
                  rotation 0.00012324637855219058 -0.9999999917933338 -3.4980888818052036e-05 5.341095070699061e-09
                  children [
                    DEF leftarm Shape {
                      appearance PBRAppearance {
                        baseColor 0.6 0 0.4
                        metalness 0
                      }
                      geometry Box {
                        size 0.01 0.04 0.04
                      }
                    }
                  ]
                  name "solid(3)"
                  boundingObject USE leftarm
                  physics Physics {
                  }
                  translationStep 0.001
                  linearVelocity -8.736940801634097e-13 8.060889903490052e-13 3.1890722701488627e-15
                  angularVelocity -2.8174785315204532e-14 -9.653008429931309e-15 -9.578310318719892e-12
                }
              }
              DEF crossbar Shape {
                appearance PBRAppearance {
                  baseColor 0.2 0.3 0.3
                  metalness 0
                }
                geometry Box {
                  size 0.01 0.1 0.01
                }
              }
            ]
            name "cross bar"
            boundingObject USE crossbar
            physics Physics {
            }
          }
          Solid {
            translation 0.04 0 0
            children [
              SliderJoint {
                jointParameters JointParameters {
                  position -3.5315963817281445e-07
                }
                device [
                  LinearMotor {
                  }
                ]
              }
            ]
          }
          DEF ab_shape Shape {
            appearance PBRAppearance {
              baseColor 0.1 0.5 1
              metalness 0
            }
            geometry Box {
              size 0.17 0.01 0.01
            }
          }
        ]
        name "solid(5)"
        boundingObject USE ab_shape
        physics Physics {
        }
        linearVelocity -9.558379624053823e-13 8.065091982944559e-13 3.3949020327081134e-15
        angularVelocity -3.728156264570222e-14 -3.563840765899957e-14 -9.580182957032395e-12
      }
    }
    Solid {
      translation 0 0 0.13
      children [
        Shape {
          appearance PBRAppearance {
            baseColor 0.6 0.4 1
            metalness 0
          }
          geometry Box {
            size 0.01 0.01 0.25
          }
        }
      ]
      name "solid(4)"
    }
    DistanceSensor {
      translation 0.073 0.037 0
      children [
        DEF distant_sensor Shape {
          appearance PBRAppearance {
            baseColor 0 0 1
            metalness 0
          }
          geometry Box {
            size 0.01 0.01 0.01
          }
        }
      ]
      name "ds front left"
      boundingObject USE distant_sensor
      physics Physics {
      }
    }
    DEF ds_side_left1 DistanceSensor {
      translation 0.069 0.045 0.019
      rotation 0 0 1 1.5707903061004251
      children [
        DEF distant_sensor Shape {
          appearance PBRAppearance {
            baseColor 0 0 1
            metalness 0
          }
          geometry Box {
            size 0.01 0.01 0.01
          }
        }
      ]
      name "ds side left1"
      boundingObject USE distant_sensor
      physics Physics {
      }
    }
    DEF ds_side_left1 DistanceSensor {
      translation -0.069 0.045 0.019
      rotation 0 0 1 1.5707903061004251
      children [
        DEF distant_sensor Shape {
          appearance PBRAppearance {
            baseColor 0 0 1
            metalness 0
          }
          geometry Box {
            size 0.01 0.01 0.01
          }
        }
      ]
      name "ds side left2"
      boundingObject USE distant_sensor
      physics Physics {
      }
    }
    DEF ds DistanceSensor {
      translation 0.073 -0.037 0
      children [
        Shape {
          appearance PBRAppearance {
            baseColor 0 0 1
            metalness 0
          }
          geometry Box {
            size 0.01 0.01 0.01
          }
        }
      ]
      name "ds front right"
      boundingObject USE distant_sensor
      physics Physics {
      }
    }
    DEF ds_side_right DistanceSensor {
      translation 0.069 -0.045 0.02
      rotation 0 0 1 -1.57
      children [
        Shape {
          appearance PBRAppearance {
            baseColor 0 0 1
            metalness 0
          }
          geometry Box {
            size 0.01 0.01 0.01
          }
        }
      ]
      name "ds side right1"
      boundingObject USE distant_sensor
      physics Physics {
      }
    }
    DEF ds_side_right DistanceSensor {
      translation -0.069 -0.045 0.02
      rotation 0 0 1 -1.57
      children [
        Shape {
          appearance PBRAppearance {
            baseColor 0 0 1
            metalness 0
          }
          geometry Box {
            size 0.01 0.01 0.01
          }
        }
      ]
      name "ds side right2"
      boundingObject USE distant_sensor
      physics Physics {
      }
    }
    HingeJoint {
      jointParameters HingeJointParameters {
        position 912.9650778336793
        axis 0 1 0
        anchor 0.05 0.056 -0.007
      }
      device [
        DEF front_left_wheel RotationalMotor {
          name "front_left_wheel"
        }
      ]
      endPoint Solid {
        translation 0.049997458215048994 0.05600000006485646 -0.007003892662634964
        rotation 0.4492655568298592 0.6322070672568548 -0.6312485117264384 2.2959716727411252
        children [
          DEF wheel Shape {
            appearance PBRAppearance {
              baseColor 0 0 0
              metalness 0
            }
            geometry Cylinder {
              height 0.01
              radius 0.02
            }
          }
        ]
        boundingObject USE wheel
        physics DEF physics_wheel Physics {
        }
        linearVelocity -4.789103642069246e-13 2.279709568160063e-13 6.381457583044093e-16
        angularVelocity 4.051957309538632e-11 -2.7778278687472057e-13 -9.576555138261003e-12
      }
    }
    HingeJoint {
      jointParameters HingeJointParameters {
        position 837.7456223124191
        axis 0 1 0
        anchor 0.05 -0.056 -0.007
      }
      device [
        DEF front_right_wheel RotationalMotor {
          name "front_right_wheel"
        }
      ]
      endPoint Solid {
        translation 0.05000711117759051 -0.0559999932750882 -0.006998664706797436
        rotation 0.38653591756301214 0.6524057400613935 -0.6518870567580441 2.4033659640938496
        children [
          USE wheel
        ]
        name "solid(1)"
        boundingObject USE wheel
        physics USE physics_wheel
        linearVelocity -4.740031676645084e-13 1.3011802956201008e-12 3.355919823424764e-15
        angularVelocity -1.2197427813106648e-10 6.442620692087705e-13 -9.582328785882375e-12
      }
    }
    HingeJoint {
      jointParameters HingeJointParameters {
        position 913.0239570659058
        axis 0 1 0
        anchor -0.05 0.056 -0.007
      }
      device [
        DEF left_back_wheel RotationalMotor {
          name "left_back_wheel"
        }
      ]
      endPoint Solid {
        translation -0.04999749989165311 0.056000001505638594 -0.007004315494384244
        rotation 0.4270933102176254 0.6396257451216649 -0.6391167425008566 2.3337326578468276
        children [
          USE wheel
        ]
        name "solid(2)"
        boundingObject USE wheel
        physics USE physics_wheel
        linearVelocity 4.816886710933973e-13 2.8860011889207586e-13 1.2722978056756024e-15
        angularVelocity -2.3072763562049315e-11 9.873575087565369e-14 -9.578571307313267e-12
      }
    }
    DEF hing HingeJoint {
      jointParameters HingeJointParameters {
        position 837.7802689886071
        axis 0 1 0
        anchor -0.05 -0.056 -0.007
      }
      device [
        RotationalMotor {
          name "right_back_wheel"
        }
      ]
      endPoint Solid {
        translation -0.049993866486821144 -0.05599999851487053 -0.007000091833871999
        rotation 0.37357132390319925 0.6561743401550902 -0.6556521190991781 2.426035401423743
        children [
          USE wheel
        ]
        name "solid(3)"
        boundingObject USE wheel
        physics USE physics_wheel
        linearVelocity 4.867125896366818e-13 1.3605826447726648e-12 -1.9082937638829227e-15
        angularVelocity -5.437680860766169e-11 3.0758300610663654e-13 -9.581200807713521e-12
      }
    }
    DEF body Shape {
      appearance PBRAppearance {
        baseColor 0 0.2 0.3
        metalness 0
      }
      geometry Box {
        size 0.15 0.1 0.03
      }
    }
  ]
  name "myrobot"
  boundingObject USE body
  physics Physics {
  }
  controller "my_keyboad_controller"
  linearVelocity 2.7974775259787523e-15 7.956188096261759e-13 4.98626481235158e-16
  angularVelocity -3.2002544989217286e-14 -9.857874840024189e-15 -9.57729396712464e-12
}
